Workbook

Sheet Listado Equipos
A1: ACTIVO | B1: PLACA NUEVA | C1: UBICACIÓN | D1: UBICACIÓN | E1: NOMBRE DEL EQUIPO | F1: MARCA | G1: MODELO | H1: SERIE | I1: FECHA DE FABRICACION | J1: FECHA DE INSTALACION | K1: FECHA DE COMPRA | L1: ACCESORIOS DEL EQUIPO | M1: VOLTAJE DE ALIMENTACION | N1: CORRIENTE DE ALIMENTACION | O1: PESO | P1: POTENCIA | Q1: DIMENSIONES | R1: FUENTE DE ALIMENTACION | S1: FRECUENCIA DE ALIMENTACION | T1: CARACTERISTICAS BATERIA | U1: CONDICIONES DE TRABAJO | V1: TEMPERATURA | W1: HUMEDAD | X1: CLASIFICACION ELECTRICA | Y1: MANEJO DE SOFTWARE | Z1: CLASIFICACION BIOMEDICA | AA1: CALIBRACION | AB1: CLASIFICACION SEGÚN RIESGO | AC1: RESPONSABLE MANTENIMIENTO | AD1: TECNOLOGIA PREDOMINANTE | AE1: FRECUENCIA MPP
A2: E000774 | C2: LABORATORIO CLINICO | D2: UNIDAD TRANSFUCIONAL | E2: AGITADOR DE PLAQUETAS | F2: HELMER | G2: PF151 | H2: 1011960 | I2: 2013 | L2: N/A | M2: 110 VAC | R2: Electrica | S2: 60 Hz | U2: Presiones de 50-60 PSI | W2: 30 - 60 %
A3: E000613 | C3: SALAS DE CIRUGIA | D3: SALA | E3: ARCO EN C | F3: PHILLIPS | G3: BV PULSERA | H3: 4574580 | I3: 2000
A4: 3393 | B4: E000355 | C4: SALAS DE CIRUGIA | D4: ESTERILIZACION | E4: AUTOCLAVE | F4: ARAWELL | G4: N/A | H4: N/A | I4: 2006 | L4: N/A | M4: 380 VAC | N4: 10A | O4: 450Kg | P4: 3600W | Q4: 100cm x 185cm x 58cm | R4: Electrica | S4: 60 Hz | T4: N/A | U4: Presiones de 50-60 PSI | V4: 0 - 150°C | W4: 30 - 80 % | X4: B clase II | Y4: NO | Z4: Soporte de Vida | AA4: SI | AB4: IIB | AC4: Ingenieria biomedica | AD4: Electroneumatica | AE4: Trimestral
A5: 1146 | C5: URGENCIAS | D5: CONSULTORIO Nº 2 | E5: BASCULA ANALOGA | F5: HEALTH O METER | G5: 233KG | H5: N/A | I5: 2013 | L5: N/A | M5: N/A | N5: N/A | O5: 15Kg | P5: N/A | Q5: 280mm x 1470mm x 560mm | R5: N/A | S5: N/A | T5: N/A | U5: Presiones de 50-60 PSI | V5: 0- 58°C | W5: 30 - 60 % | X5: N/A | Y5: N/A | Z5: Diagnostico | AA5: SI | AB5: I | AC5: Ingenieria biomedica | AD5: Mecanica | AE5: Trimestral
B6: E000232 | C6: URGENCIAS | D6: CONSULTORIO | E6: BASCULA PESA BEBE | F6: HEALTH O METER | G6: 386KG | H6: 259713 | I6: 2002 | L6: N/A | M6: N/A | N6: N/A | O6: 15Kg | P6: N/A | Q6: 280mm x 1470mm x 560mm | R6: N/A | S6: N/A | T6: N/A | U6: Presiones de 50-60 PSI | V6: 0- 58°C | W6: 30 - 60 % | X6: N/A | Y6: N/A | Z6: Diagnostico | AA6: SI | AB6: I | AC6: Ingenieria biomedica | AD6: Mecanica | AE6: Trimestral
A7: E000360 | C7: UCI 4 PISO | D7: STAR DE ENFERMERIA | E7: BOMBA DE CONTRAPULSACION | F7: ARROW | G7: ACAT I PLUS | H7: OO9282A | I7: 2007
A8: 5481 | B8: E000339 | C8: SALAS DE CIRUGIA | D8: RESERVA | E8: CALENTADOR DE LIQUIDOS | F8: ANIMEC | G8: AM-2S | H8: 2250026 | I8: 2013
A9: 5413 | B9: E000196 | C9: LABORATORIO CLINICO | D9: CENTRIFUGACION | E9: CENTRIFUGA | F9: HUMAN | G9: HUMAN 4K | H9: 02 3674 | I9: 2004 | L9: N/A | M9: 110 VAC | N9: 1,5A | O9: 40Kg | P9: 310W | Q9: 32cm x 41cm x 49cm | R9: Electrica | S9: 60 Hz | T9: N/A | U9: Presiones de 50-60 PSI | V9: 0 - 55°C | W9: 30 - 60 % | X9: B clase I | Y9: NO | Z9: Lab. Clinico | AA9: SI | AB9: IIA | AC9: Ingenieria biomedica | AD9: Electronica | AE9: Trimestral
B10: E000192 | C10: LABORATORIO CLINICO | D10: COAGULACION | E10: CONTADOR DE CELULAS | F10: CLAY ADAMS | G10: N/A | H10: N/A | I10: 2001
A11: N/A | C11: SALAS DE CIRUGIA | D11: RESERVA | E11: DERMATOMO | F11: NOUVAG | G11: TCM3000 | H11: LK1913 | I11: 2003
A12: E000610 | C12: UCI 4 PISO | D12: CARRO DE PARO | E12: DESFIBRILADOR | F12: MINDRAY | G12: BENEHEART D3 | H12: EL-32006198 | I12: 2013 | L12: Cable ECG, Cable AC, Palas | M12: 110 VAC | N12: 6A | O12: 12Kg | P12: 500W | Q12: 18cm x 32cm x 49cm | R12: Electrica | S12: 60 Hz | T12: 10V 140mA | U12: Presiones de 50-60 PSI | V12: 5 - 50°C | W12: 30 - 60 % | X12: CF clase II | Y12: NO | Z12: Soporte de Vida | AA12: SI | AB12: IIB | AC12: Ingenieria biomedica | AD12: Electronica | AE12: Trimestral
A13: E000740 | C13: UCI 2 PISO | D13: CARRO DE PARO | E13: DESFIBRILADOR | F13: MINDRAY | G13: BENEHEART D3 | H13: EL-35007533 | I13: 2012 | L13: Cable ECG, Cable AC, Palas | M13: 110 VAC | N13: 6A | O13: 12Kg | P13: 500W | Q13: 18cm x 32cm x 49cm | R13: Electrica | S13: 60 Hz | T13: 10V 140mA | U13: Presiones de 50-60 PSI | V13: 5 - 50°C | W13: 30 - 60 % | X13: CF clase II | Y13: NO | Z13: Soporte de Vida | AA13: SI | AB13: IIB | AC13: Ingenieria biomedica | AD13: Electronica | AE13: Trimestral
A14: 1210 | C14: UCI TERCER PISO | D14: CARRO DE PARO | E14: DESFIBRILADOR | F14: GENERAL ELECTRIC | G14: CARDIOSERV | H14: 101127877 | I14: 2006 | L14: Cable ECG, Cable AC, Palas | M14: 110 VAC | N14: 6A | O14: 12Kg | P14: 500W | Q14: 18cm x 32cm x 49cm | R14: Electrica | S14: 60 Hz | T14: 10V 140mA | U14: Presiones de 50-60 PSI | V14: 5 - 50°C | W14: 30 - 60 % | X14: CF clase II | Y14: NO | Z14: Soporte de Vida | AA14: SI | AB14: IIB | AC14: Ingenieria biomedica | AD14: Electronica | AE14: Trimestral
A15: E000580 | C15: UCI CORONARIA | D15: CARRO DE PARO | E15: DESFIBRILADOR | F15: ZOLL | G15: PD1400 | H15: D97K13162 | I15: 1999 | L15: Cable ECG, Cable AC, Palas | M15: 110 VAC | N15: 6A | O15: 12Kg | P15: 500W | Q15: 18cm x 32cm x 49cm | R15: Electrica | S15: 60 Hz | T15: 10V 140mA | U15: Presiones de 50-60 PSI | V15: 5 - 50°C | W15: 30 - 60 % | X15: CF clase II | Y15: NO | Z15: Soporte de Vida | AA15: SI | AB15: IIB | AC15: Ingenieria biomedica | AD15: Electronica | AE15: Trimestral
A16: 3336 | B16: E000358 | C16: SALAS DE CIRUGIA | D16: SALA | E16: DESFIBRILADOR | F16: HEWLETT PACKARD | G16: M1722B | H16: US00110634 | I16: 1999 | L16: Cable ECG, Cable AC, Palas | M16: 110 VAC | N16: 6A | O16: 12Kg | P16: 500W | Q16: 18cm x 32cm x 49cm | R16: Electrica | S16: 60 Hz | T16: 10V 140mA | U16: Presiones de 50-60 PSI | V16: 5 - 50°C | W16: 30 - 60 % | X16: CF clase II | Y16: NO | Z16: Soporte de Vida | AA16: SI | AB16: IIB | AC16: Ingenieria biomedica | AD16: Electronica | AE16: Trimestral
A17: E000639 | C17: RADIOLOGIA | D17: ECOGRAFIAS | E17: ECOGRAFO DE ALTA DEFINICION | F17: PHILLIPS | G17: HD6 | H17: CIN70130081 | I17: 2012
A18: 1420 | C18: SALAS DE CIRUGIA | D18: SALA | E18: ELECTROBISTURI | F18: VALLEYLAB | G18: FORCE 2 | H18: F7L33778T | I18: 2003 | L18: Cable AC, Pedal Bipolar, Pedal Monopolar | M18: 110 VAC | N18: 7A | O18: 18,2Kg | P18: 800W | Q18: 15,9cm x 40,4cm x 57,8cm | R18: Electrica | S18: 60 Hz | T18: N/A | U18: Presiones de 50-60 PSI | V18: 3 - 65°C | W18: 30 - 60 % | X18: CF clase II | Y18: NO | Z18: Tratamiento | AA18: SI | AB18: IIB | AC18: Ingenieria biomedica | AD18: Electronica | AE18: Trimestral
A19: 1765 | C19: SALAS DE CIRUGIA | D19: SALA | E19: ELECTROBISTURI | F19: CONMED ASPEN | G19: SABRE 2400 | H19: AF049221 | I19: 2001 | L19: Cable AC, Pedal Bipolar, Pedal Monopolar | M19: 110 VAC | N19: 7A | O19: 18,2Kg | P19: 800W | Q19: 15,9cm x 40,4cm x 57,8cm | R19: Electrica | S19: 60 Hz | T19: N/A | U19: Presiones de 50-60 PSI | V19: 3 - 65°C | W19: 30 - 60 % | X19: CF clase II | Y19: NO | Z19: Tratamiento | AA19: SI | AB19: IIB | AC19: Ingenieria biomedica | AD19: Electronica | AE19: Trimestral
A20: 6099 | C20: URGENCIAS | D20: REANIMACION (URGENCIAS) | E20: ELECTROCARDIOGRAFO | F20: EDAN | G20: SE-601C | H20: SEA33231070820D | I20: 2011 | L20: Cable AC, Cable ECG, Pinzas(4), Pera Precordial(6), Rollo de Papel, Cable Tierra. | M20: 110 VAC | N20: 900mA | O20: 2,3Kg | P20: 180W | Q20: 278mm x 210mm x 50mm | R20: Electrica | S20: 60 Hz | T20: 14V | U20: Presiones de 50-60 PSI | V20: 2 - 48°C | W20: 30 - 60 % | X20: CF Clase I | Y20: NO | Z20: Diagnostico | AA20: SI | AB20: IIA | AC20: Ingenieria biomedica | AD20: Electronica | AE20: Bimestral
A21: 1490 | C21: URGENCIAS | D21: TRIAGE | E21: EQUIPO DE ORGANOS | F21: WELCH ALLYN | G21: 19090 | H21: N/A | I21: 2010 | L21: cable ac, cabezales | M21: 110 VAC | N21: 0,5A | Q21: 5-32 cm | R21: Electrica | S21: 60 Hz | T21: N/A | U21: Presiones de 50-60 PSI | V21: 0 - 55°C | W21: 30 - 60 % | X21: B clase I | Y21: NO | Z21: diagnostico | AA21: NO | AB21: IIA | AC21: Ingenieria biomedica | AD21: Electrica | AE21: Semestral
A22: 4374 | B22: E000365 | C22: SALAS DE CIRUGIA | D22: RESERVA | E22: ESTIMULADOR DE NERVIO PERIFERICO | F22: LIFE-TECH | G22: MINISTIM MS-IV A | H22: OF1570004 | I22: 2013
A23: 1493 | B23: EOOO485 | C23: UCI 4 PISO | D23: HABITACION | E23: FLUJOMETRO SENCILLO | F23: WHITE MARTINS | G23: J95 | H23: N/A | I23: 2005
A24: 1207 | C24: HOSPITALIZACION 7 SUR | D24: CARRO DE PARO | E24: FONENDOSCOPIO | F24: GENERICO | G24: N/A | H24: N/A | I24: 2010
A25: N/A | C25: SALAS DE CIRUGIA | D25: RESERVA | E25: FOTOSFORO QUIRURGICO | F25: WOLF | G25: 4526.00 | H25: N/A | I25: 2006 | L25: Adapador Voltaje | M25: 110 VAC | N25: 300mA | O25: 120gr | P25: 75W | Q25: 4 - 15 cm | R25: Electrica | S25: 60 Hz | T25: N/A | U25: Presiones de 50-60 PSI | V25: 0 - 55°C | W25: 30 - 60 % | X25: B clase I | Y25: NO | Z25: Tratamiento | AA25: NO | AB25: IIA | AC25: Ingenieria biomedica | AD25: Electrica | AE25: Semestral
A26: 1466 | C26: SALAS DE CIRUGIA | D26: SALA | E26: LAMPARA CIELITICA | F26: MARTIN | G26: ML701 | H26: 060199D153 | I26: 2004 | L26: N/A | M26: 220 VAC | N26: 2A | O26: 60Kg | P26: 425W | Q26: 120cm x 130cm x 116cm | R26: Electrica | S26: 60 Hz | T26: N/A | U26: Presiones de 50-60 PSI | V26: 0 - 70°C | W26: 30 - 60 % | X26: B clase I | Y26: NO | Z26: Tratamiento | AA26: NO | AB26: IIA | AC26: Ingenieria biomedica | AD26: Electrica | AE26: Semestral
A27: 3344 | C27: SALAS DE CIRUGIA | D27: SALA | E27: LAMPARA CIELITICA | F27: AMSCO | G27: POLARIS SL | H27: N/A | I27: 2006 | L27: N/A | M27: 220 VAC | N27: 2A | O27: 60Kg | P27: 425W | Q27: 120cm x 130cm x 116cm | R27: Electrica | S27: 60 Hz | T27: N/A | U27: Presiones de 50-60 PSI | V27: 0 - 70°C | W27: 30 - 60 % | X27: B clase I | Y27: NO | Z27: Tratamiento | AA27: NO | AB27: IIA | AC27: Ingenieria biomedica | AD27: Electrica | AE27: Semestral
A28: 1422 | C28: SALAS DE CIRUGIA | D28: SALA | E28: LAMPARA CIELITICA | F28: CASTLE | G28: 5116851 | H28: LG961018-19 | I28: 2004 | L28: N/A | M28: 220 VAC | N28: 2A | O28: 60Kg | P28: 425W | Q28: 120cm x 130cm x 116cm | R28: Electrica | S28: 60 Hz | T28: N/A | U28: Presiones de 50-60 PSI | V28: 0 - 70°C | W28: 30 - 60 % | X28: B clase I | Y28: NO | Z28: Tratamiento | AA28: NO | AB28: IIA | AC28: Ingenieria biomedica | AD28: Electrica | AE28: Semestral
A29: 1436 | C29: SALAS DE CIRUGIA | D29: SALA | E29: LAMPARA CIELITICA | F29: CASTLE | G29: 5116851 | H29: LG961020-21 | I29: 2004 | L29: N/A | M29: 220 VAC | N29: 2A | O29: 60Kg | P29: 425W | Q29: 120cm x 130cm x 116cm | R29: Electrica | S29: 60 Hz | T29: N/A | U29: Presiones de 50-60 PSI | V29: 0 - 70°C | W29: 30 - 60 % | X29: B clase I | Y29: NO | Z29: Tratamiento | AA29: NO | AB29: IIA | AC29: Ingenieria biomedica | AD29: Electrica | AE29: Semestral
A30: 1759 | C30: HOSPITALIZACION 6 SUR | D30: CARRO DE PARO | E30: LARINGOSCOPIO | F30: WELCH ALLYN | G30: 60300 | H30: N/A | I30: 2009 | L30: N/A | M30: 9VDC | R30: Electrica | T30: NO | U30: Presiones de 50-60 PSI | V30: 10 - 70°C | W30: 30 - 60 % | X30: clase III | Y30: NO | Z30: Tratamiento | AA30: NO | AB30: I | AC30: Ingenieria biomedica | AD30: electrico | AE30: Semestral
A31: E000649 | C31: SALAS DE CIRUGIA | D31: SALA | E31: MAQUINA DE ANESTESIA | F31: MINDRAY | G31: WATO-EX65 | H31: ER-33001386 | I31: 2012 | L31: N/A | M31: 110 VAC | N31: 1,8A | O31: 134,2Kg | P31: 750W | Q31: 103,5cm x 132cm x 84cm | R31: Electrica | S31: 60 Hz | T31: 6V | U31: Presiones de 50-60 PSI | V31: 0 - 43°C | W31: 30 - 60 % | X31: BF clase II | Y31: NO | Z31: Soporte de Vida | AA31: SI | AB31: IIB | AC31: Ingenieria biomedica | AD31: Electroneumatica | AE31: Bimestral
A32: 4001 | B32: E000073 | C32: UCI CORONARIA | D32: CARRO DE PARO | E32: MARCAPASOS EXTERNO | F32: MEDTRONIC | G32: 5375 | H32: CE0010825R | I32: 2007 | L32: Cable ECG | M32: N/A | N32: N/A | O32: 2Kg | P32: 60W | Q32: 14cm x 9cm x 4cm | R32: Bateria | S32: N/A | T32: 9V 200mA | U32: Presiones de 50-60 PSI | V32: 0 - 60°C | W32: 30 - 60 % | X32: CF clase I | Y32: NO | Z32: Diagnostico | AA32: SI | AB32: IIB | AC32: Ingenieria biomedica | AD32: Electronica | AE32: Semestral
A33: 4452 | B33: E000364 | C33: URGENCIAS | D33: REANIMACION | E33: MARCAPASOS EXTERNO BICAMERAL | F33: MEDTRONIC | G33: 5330 | H33: EH000064512 | I33: 2004 | L33: Cable ECG | M33: N/A | N33: N/A | O33: 2Kg | P33: 60W | Q33: 14cm x 9cm x 4cm | R33: Bateria | S33: N/A | T33: 9V 200mA | U33: Presiones de 50-60 PSI | V33: 0 - 60°C | W33: 30 - 60 % | X33: CF clase I | Y33: NO | Z33: Diagnostico | AA33: SI | AB33: IIB | AC33: Ingenieria biomedica | AD33: Electronica | AE33: Semestral
A34: 1425 | C34: SALAS DE CIRUGIA | D34: SALA | E34: MESA DE CIRUGIA | F34: SHAMPAINE | G34: 4900B | H34: RL9611019 | I34: 1997 | L34: Cable AC, Control de Mando | M34: 110 VAC | N34: 3A | O34: 250Kg | P34: 480W | Q34: 1842mm x 502mm | R34: Electrica | S34: 60 Hz | T34: 24V | U34: Presiones de 50-60 PSI | V34: 0 - 68°C | W34: 30 - 60 % | X34: B clase I | Y34: NO | Z34: Tratamiento | AA34: NO | AB34: IIA | AC34: Ingenieria biomedica | AD34: Electrohidraulica | AE34: trimestral
A35: E000616 | C35: SALAS DE CIRUGIA | D35: SALA | E35: MESA DE CIRUGIA | F35: SHAMPAINE | G35: 600 | H35: N/A | I35: 1994 | L35: Cable AC, Control de Mando | M35: 110 VAC | N35: 3A | O35: 250Kg | P35: 480W | Q35: 1842mm x 502mm | R35: Electrica | S35: 60 Hz | T35: 24V | U35: Presiones de 50-60 PSI | V35: 0 - 68°C | W35: 30 - 60 % | X35: B clase I | Y35: NO | Z35: Tratamiento | AA35: NO | AB35: IIA | AC35: Ingenieria biomedica | AD35: Electrohidraulica | AE35: trimestral
A36: 1468 | C36: SALAS DE CIRUGIA | D36: SALA | E36: MESA DE CIRUGIA | F36: GENERICA | G36: N/A | H36: N/A | I36: 1998 | L36: Cable AC, Control de Mando | M36: 110 VAC | N36: 3A | O36: 250Kg | P36: 480W | Q36: 1842mm x 502mm | R36: Electrica | S36: 60 Hz | T36: 24V | U36: Presiones de 50-60 PSI | V36: 0 - 68°C | W36: 30 - 60 % | X36: B clase I | Y36: NO | Z36: Tratamiento | AA36: NO | AB36: IIA | AC36: Ingenieria biomedica | AD36: Electrohidraulica | AE36: trimestral
A37: 3345 | C37: SALAS DE CIRUGIA | D37: SALA | E37: MESA DE CIRUGIA | F37: AMSCO | G37: 2080L | H37: 435185082 | I37: 1996 | L37: Cable AC, Control de Mando | M37: 110 VAC | N37: 3A | O37: 250Kg | P37: 480W | Q37: 1842mm x 502mm | R37: Electrica | S37: 60 Hz | T37: 24V | U37: Presiones de 50-60 PSI | V37: 0 - 68°C | W37: 30 - 60 % | X37: B clase I | Y37: NO | Z37: Tratamiento | AA37: NO | AB37: IIA | AC37: Ingenieria biomedica | AD37: Electrohidraulica | AE37: trimestral
A38: E000652 | C38: LABORATORIO CLINICO | D38: LABORATORIO CLINICO | E38: MICROSCOPIO | F38: OLYMPUS | G38: CX-22 | H38: 2H85414 | I38: 2012 | L38: Cable AC | M38: 110 VAC | N38: 2.2A | P38: 50W | R38: Electrica | S38: 60 Hz | T38: N/A | U38: Presiones de 50-60 PSI | V38: 15 - 53°C | W38: 30 - 60 % | X38: B Clase II | Y38: si | Z38: apoyo y tratamiento | AB38: IIB | AC38: Ingenieria biomedica | AD38: electromecanica | AE38: Semestral
A39: 2060 | B39: E000368 | C39: SALAS DE CIRUGIA | D39: SALA | E39: MINI DOPPLER | F39: KOVEN | G39: ES 100X | H39: N/A | I39: 2008
A40: E000659 | C40: UCI TERCER PISO | D40: CUBICULO | E40: MONITOR DE SIGNOS VITALES | F40: EDAN | G40: M8 | H40: 301301-M13303440026 | I40: 2012 | L40: Cable AC, Cable ECG, sensor SPO2, Cable PI, Brazalete, Manguera, sensor de T. | M40: 110 VAC | N40: 2A | O40: 4Kg | P40: 220W | Q40: 252mm x 246mm x 118mm | R40: Electrica | S40: 60 Hz | T40: 12V 500mA | U40: Presiones de 50-60 PSI | V40: 5 - 48 °C | W40: 30 - 60 % | X40: BF clase I | Y40: SI | Z40: Diagnostico | AA40: SI | AB40: IIB | AC40: Ingenieria biomedica | AD40: Electronica | AE40: Bimestral
...

Sheet Ficha Tecnica
A1: HOSPITAL SANTA RITA DEL SOCORRO | F1: FO-MT-05
A2: DIRECCIÓN ADMINISTRATIVA | F2: Versión: 0,1
A3: FORMATO FICHA TÉCNICA EQUIPO | F3: Fecha: 2013-04
A4: ÁREA DE MANTENIMIENTO | F4: Página: 1 de 1
A5: NOMBRE DEL EQUIPO | C5: =VLOOKUP(F13,'Listado Equipos'!A1:AE68,3,0) -> #N/A | E5: FORMA DE | F5: DIRECTA | G5: COMODATO | H5: A. TÉCNICA
E6: ADQUISICIÓN | F6: X
A7: MARCA | C7: =VLOOKUP(F13,'Listado Equipos'!A1:AE68,4,0) -> #N/A | E7: MODELO | F7: =VLOOKUP(F13,'Listado Equipos'!A1:AE68,5,0) -> #N/A
A9: SERIE | C9: =VLOOKUP(F13,'Listado Equipos'!A1:AE68,6,0) -> #N/A | E9: FECHA DE | F9: =VLOOKUP(F13,'Listado Equipos'!A1:AE68,8,0) -> #N/A
E10: INSTALACIÓN
A11: FECHA DE FABRICACIÓN | C11: =VLOOKUP(F13,'Listado Equipos'!A1:AE68,7,0) -> #N/A | E11: FECHA DE | F11: =VLOOKUP(F13,'Listado Equipos'!A1:AE68,9,0) -> #N/A
E12: COMPRA
A13: SERVICIO | C13: =VLOOKUP(F13,'Listado Equipos'!A1:AD68,2,0) -> #N/A | E13: ACTIVO | F13: 0
A15: UBICACIÓN DEL EQUIPO | C15: =VLOOKUP(F13,'Listado Equipos'!A1:AD41,3,0) -> #N/A
A16: ACCESORIOS DEL EQUIPO (SI ES APLICABLE):
A17: =VLOOKUP(F13,'Listado Equipos'!A1:AE68,11,0) -> #N/A
A19: CARACTERÍSTICAS TÉCNICAS (diligenciar en caso aplicable)
A20: Voltaje de alimentación: | D20: Corriente de Alimentación: | F20: Peso:
A21: =VLOOKUP(F13,'Listado Equipos'!A1:AE68,12,0) -> #N/A | D21: =VLOOKUP(F13,'Listado Equipos'!A1:AE68,13,0) -> #N/A | F21: =VLOOKUP(F13,'Listado Equipos'!A1:AE68,14,0) -> #N/A
A22: Potencia: | D22: Dimensiones: | F22: Fuente de Alimentacion:
A23: =VLOOKUP(F13,'Listado Equipos'!A1:AE68,15,0) -> #N/A | D23: =VLOOKUP(F13,'Listado Equipos'!A1:AE68,16,0) -> #N/A | F23: =VLOOKUP(F13,'Listado Equipos'!A1:AE68,17,0) -> #N/A
A24: Frecuencia de alimentación: | D24: Caracteristicas Bateria: | F24: Condiciones de trabajo:
A25: =VLOOKUP(F13,'Listado Equipos'!A1:AE68,18,0) -> #N/A | D25: =VLOOKUP(F13,'Listado Equipos'!A1:AE68,19,0) -> #N/A | F25: =VLOOKUP(F13,'Listado Equipos'!A1:AE68,20,0) -> #N/A
A26: Temperatura: | E26: Humedad:
A27: =VLOOKUP(F13,'Listado Equipos'!A1:AE68,21,0) -> #N/A | E27: =VLOOKUP(F13,'Listado Equipos'!A1:AE68,22,0) -> #N/A
A28: GESTION TECNOLOGICA
A29: Clasificacion Electrica: | D29: Manejo de Software: | F29: Clasificacion Biomedica:
A30: =VLOOKUP(F13,'Listado Equipos'!A1:AE68,23,0) -> #N/A | D30: =VLOOKUP(F13,'Listado Equipos'!A1:AE8,264,0) -> #N/A | F30: =VLOOKUP(F13,'Listado Equipos'!A1:AE68,25,0) -> #N/A
A31: Calibracion: | D31: Registro Invima: | F31: Clasificación según riesgo:
A32: =VLOOKUP(F13,'Listado Equipos'!A1:AE68,26,0) -> #N/A | D32: =VLOOKUP(F13,'Listado Equipos'!A1:AE68,27,0) -> #N/A | F32: =VLOOKUP(F13,'Listado Equipos'!A1:AE68,28,0) -> #N/A
A33: Rsponsable Mantenimiento: | D33: Tecnologia Predominante:
A34: =VLOOKUP(F13,'Listado Equipos'!A1:AE68,29,0) -> #N/A | D34: =VLOOKUP(F13,'Listado Equipos'!A1:AE68,30,0) -> #N/A
A35: FRECUENCIA DE MANTENIMIENTO PREVENTIVO
A36: =VLOOKUP(F13,'Listado Equipos'!A1:AE68,31,0) -> #N/A

Sheet MPP
A1: CRONOGRAMA DE MANTENIMIENTO PREVENTIVO PROGRAMADO
A2: EQUIPO | B2: SERVICIO | C2: VARIABLES | G2: TOTAL | H2: PERIODO DE MPP | J2: RANGOS | K2: PERIODO DE MPP
C3: FRECUENCIA USO | D3: FORMA DE USO (TRATO) | E3: EXACTITUD REQUERIDA | F3: IMPORTANCIA $ | J3: 4 A 8 | K3: ANUAL
A4: MONITOR MULTIPARAMETROS | B4: UCI 4 PISO | C4: 5 | D4: 5 | E4: 5 | F4: 4 | G4: 19 | H4: BIMESTRAL | J4: 9 A 13 | K4: SEMESTRAL
A5: MARCAPASOS EXTERNO | B5: UCI 2 PISO | C5: 4 | D5: 2 | E5: 5 | F5: 3 | G5: 14 | H5: TRIMESTRAL | J5: 14 A 17 | K5: TRIMESTRAL
A6: DESFIBRILADOR | B6: UCI 4 PISO | C6: 2 | D6: 5 | E6: 5 | F6: 4 | G6: 16 | H6: TRIMESTRAL | J6: 18 A 20 | K6: BIMESTRAL
A7: BOMBA DE CONTRAPULSACION | B7: SALAS DE CIRUGIA | C7: 4 | D7: 4 | E7: 5 | F7: 5 | G7: 18 | H7: BIMESTRAL
A8: BASCULA CON TALLIMETRO | B8: CONSULTA EXTERNA | C8: 5 | D8: 3 | E8: 4 | F8: 2 | G8: 14 | H8: TRIMESTRAL
A9: PESA BEBE DIGITAL | B9: URGENCIAS | C9: 3 | D9: 3 | E9: 5 | F9: 3 | G9: 14 | H9: TRIMESTRAL
A10: ECOGRAFO | B10: IMAGENOLOGIA | C10: 5 | D10: 3 | E10: 5 | F10: 5 | G10: 18 | H10: BIMESTRAL
A11: HEMOCRON | B11: SALAS DE CIRUGIA | C11: 3 | D11: 3 | E11: 5 | F11: 4 | G11: 15 | H11: TRIMESTRAL
A12: ELECTROBISTURI | B12: SALAS DE CIRUGIA | C12: 4 | D12: 4 | E12: 4 | F12: 4 | G12: 16 | H12: TRIMESTRAL
A13: AUTOCLAVE | B13: SALAS DE CIRUGIA | C13: 5 | D13: 4 | E13: 4 | F13: 4 | G13: 17 | H13: TRIMESTRAL
A14: STERRAD | B14: SALAS DE CIRUGIA | C14: 5 | D14: 3 | E14: 4 | F14: 5 | G14: 17 | H14: TRIMESTRAL
A15: ELECTROCARDIOGRAFO | B15: URGENCIAS | C15: 4 | D15: 5 | E15: 5 | F15: 4 | G15: 18 | H15: BIMESTRAL
A16: FOTOFORO QUIRURGICO | B16: SALAS DE CIRUGIA | C16: 3 | D16: 2 | E16: 1 | F16: 3 | G16: 9 | H16: SEMESTRAL
A17: LAMPARA CIELITICA | B17: SALAS DE CIRUGIA | C17: 5 | D17: 3 | E17: 1 | F17: 4 | G17: 13 | H17: SEMESTRAL
A18: VENTILADOR | B18: TERAPIA RESPIRATORIA | C18: 5 | D18: 4 | E18: 5 | F18: 5 | G18: 19 | H18: BIMESTRAL
... A28: LAMPARA DE CALOR RADIANTE | B28: URGENCIAS | C28: 2 | D28: 3 | E28: 5 | F28: 4 | G28: 14 | H28: TRIMESTRAL

Sheet Predicitivo
A1: UNIDAD O SERVICIO | B1: EQUIPOS | C1: LUNES | D1: MARTES | E1: MIERCOLES | F1: JUEVES | G1: VIERNES | H1: SABADO
A2: CIRUGIA GENERAL | B2: BOMBA DE CONTRAPULSACION | C2: X | D2: X | E2: X | F2: X | G2: X | H2: DISPONIBILIDAD
B3: HEMOCRON | C3: X | D3: X | E3: X | F3: X | G3: X | H3: DISPONIBILIDAD
B4: ELECTROBISTURI | C4: X | D4: X | E4: X | F4: X | G4: X | H4: DISPONIBILIDAD
B5: AUTOCLAVE | C5: X | D5: X | E5: X | F5: X | G5: X | H5: DISPONIBILIDAD
B6: STERRAD | C6: X | D6: X | E6: X | F6: X | G6: X | H6: DISPONIBILIDAD
B7: FOTOFORO QUIRURGICO | C7: X | D7: X | E7: X | F7: X | G7: X | H7: DISPONIBILIDAD
B8: LAMPARA CIELITICA | C8: X | D8: X | E8: X | F8: X | G8: X | H8: DISPONIBILIDAD
B9: MAQUINA DE ANESTESIA | C9: X | D9: X | E9: X | F9: X | G9: X | H9: DISPONIBILIDAD
B10: MARCAPASOS EXTERNO BICAMERAL | C10: X | D10: X | E10: X | F10: X | G10: X | H10: DISPONIBILIDAD
B11: MESA DE CIRUGIA | C11: X | D11: X | E11: X | F11: X | G11: X | H11: DISPONIBILIDAD
B12: TORNIQUETE ELECTRICO | C12: X | D12: X | E12: X | F12: X | G12: X | H12: DISPONIBILIDAD
A13: UCI 2 Y 4 PISO | B13: MONITOR MULTIPARAMETROS | C13: X | E13: X | G13: X | H13: DISPONIBILIDAD
B14: MARCAPASOS EXTERNO | C14: X | E14: X | G14: X | H14: DISPONIBILIDAD
B15: DESFIBRILADOR | C15: X | E15: X | G15: X | H15: DISPONIBILIDAD
A16: URGENCIAS | B16: PESA BEBE DIGITAL | D16: X | F16: X | H16: DISPONIBILIDAD
B17: LAMPARA DE CALOR RADIANTE | D17: X | F17: X | H17: DISPONIBILIDAD
A18: IMAGENOLOGIA | B18: ECOGRAFO | C18: X | E18: X | G18: X | H18: DISPONIBILIDAD
B19: RAYOS X CONVENCIONAL FIJO | C19: X | E19: X | G19: X | H19: DISPONIBILIDAD
A20: TERAPIA RESPIRATORIA | B20: VENTILADOR 760 | C20: X | D20: X | E20: X | F20: X | G20: X | H20: DISPONIBILIDAD
B21: VENTILADOR 840 | C21: X | D21: X | E21: X | F21: X | G21: X | H21: DISPONIBILIDAD
A22: LABORATORIO CLINICO | B22: CENTRIFUGA | C22: X | H22: DISPONIBILIDAD
A23: UNIDAD RENAL | B23: MQUINA DE HEMODIALISIS | C23: X | D23: X | E23: X | F23: X | G23: X | H23: DISPONIBILIDAD
A24: TERAPIA FISICA | B24: ULTRASONIDO | E24: X | H24: DISPONIBILIDAD
A25: CONSULTA EXTERNA | B25: BASCULA CON TALLIMETRO | G25: X
